<?xml version="1.0" ?>
<!-- =================================================================================== -->
<!-- |    This document was autogenerated by xacro from xarm_1s.urdf.xacro             | -->
<!-- |    EDITING THIS FILE BY HAND IS NOT RECOMMENDED                                 | -->
<!-- =================================================================================== -->
<robot name="xarm_1s">
  <ros2_control name="RobotArm" type="system">
    <hardware>
      <plugin>robotic_arm_controllers/RoboticArmHWInterface</plugin>
      <param name="port_">/dev/ttyUSB0</param>
      <!--<param name="baud_rate">9600</param>-->
    </hardware>
    <!-- Interfaces -->
    <joint name="shoulder_pan">
      <command_interface name="position">
        <param name="min">-1.57</param>
        <param name="max">1.57</param>
      </command_interface>
      <state_interface name="position"/>
    </joint>
    <joint name="shoulder_lift">
      <command_interface name="position">
        <param name="min">-1.57</param>
        <param name="max">1.57</param>
      </command_interface>
      <state_interface name="position"/>
    </joint>
    <joint name="elbow">
      <command_interface name="position">
        <param name="min">-1.57</param>
        <param name="max">1.57</param>
      </command_interface>
      <state_interface name="position"/>
    </joint>
    <joint name="wrist_flex">
      <command_interface name="position">
        <param name="min">1.57</param>
        <param name="max">-1.57</param>
      </command_interface>
      <state_interface name="position"/>
    </joint>
    <joint name="wrist_roll">
      <command_interface name="position">
        <param name="min">-1.57</param>
        <param name="max">1.57</param>
      </command_interface>
      <state_interface name="position"/>
    </joint>
    <joint name="grip_left">
      <command_interface name="position">
        <param name="min">-1.57</param>
        <param name="max">0.0</param>
      </command_interface>
      <state_interface name="position"/>
    </joint>
  </ros2_control>
  <link name="base_link">
    <visual>
      <geometry>
        <mesh filename="package://xarm_1s_description/meshes/base.stl"/>
      </geometry>
    </visual>
  </link>
  <link name="shoulder_link">
    <visual>
      <geometry>
        <mesh filename="package://xarm_1s_description/meshes/shoulder.stl"/>
      </geometry>
    </visual>
  </link>
  <link name="humerus_link">
    <visual>
      <geometry>
        <mesh filename="package://xarm_1s_description/meshes/humerus.stl"/>
      </geometry>
    </visual>
  </link>
  <link name="forearm_link">
    <visual>
      <geometry>
        <mesh filename="package://xarm_1s_description/meshes/forearm.stl"/>
      </geometry>
    </visual>
  </link>
  <link name="wrist_link">
    <visual>
      <geometry>
        <mesh filename="package://xarm_1s_description/meshes/wrist.stl"/>
      </geometry>
    </visual>
  </link>
  <link name="hand_link">
    <visual>
      <geometry>
        <mesh filename="package://xarm_1s_description/meshes/hand.stl"/>
      </geometry>
    </visual>
  </link>
  <link name="grip_left_link">
    <visual>
      <geometry>
        <mesh filename="package://xarm_1s_description/meshes/carpal-left.stl"/>
      </geometry>
    </visual>
  </link>
  <link name="grip_right_link">
    <visual>
      <geometry>
        <mesh filename="package://xarm_1s_description/meshes/carpal-right.stl"/>
      </geometry>
    </visual>
  </link>
  <link name="tendon_left_link">
    <visual>
      <geometry>
        <mesh filename="package://xarm_1s_description/meshes/tendon.stl"/>
      </geometry>
    </visual>
  </link>
  <link name="tendon_right_link">
    <visual>
      <geometry>
        <mesh filename="package://xarm_1s_description/meshes/tendon.stl"/>
      </geometry>
    </visual>
  </link>
  <link name="finger_left_link">
    <visual>
      <geometry>
        <mesh filename="package://xarm_1s_description/meshes/finger.stl"/>
      </geometry>
    </visual>
  </link>
  <link name="finger_right_link">
    <visual>
      <origin rpy="0 0 3.14159"/>
      <geometry>
        <mesh filename="package://xarm_1s_description/meshes/finger.stl"/>
      </geometry>
    </visual>
  </link>
  <joint name="shoulder_pan" type="revolute">
    <parent link="base_link"/>
    <child link="shoulder_link"/>
    <origin xyz="0 0 0.059"/>
    <axis xyz="0 0 1"/>
    <limit effort="1000" lower="-1.57" upper="1.57" velocity="0.5"/>
  </joint>
  <joint name="shoulder_lift" type="revolute">
    <parent link="shoulder_link"/>
    <child link="humerus_link"/>
    <origin xyz="-0.010 0 0.028"/>
    <axis xyz="0 -1 0"/>
    <limit effort="1000" lower="-1.57" upper="1.57" velocity="0.5"/>
  </joint>
  <joint name="elbow" type="revolute">
    <parent link="humerus_link"/>
    <child link="forearm_link"/>
    <origin xyz="0 0 0.105"/>
    <axis xyz="0 1 0"/>
    <limit effort="1000" lower="-1.57" upper="1.57" velocity="0.5"/>
  </joint>
  <joint name="wrist_flex" type="revolute">
    <parent link="forearm_link"/>
    <child link="wrist_link"/>
    <origin xyz="0 0 0.090"/>
    <axis xyz="0 -1 0"/>
    <limit effort="1000" lower="1.57" upper="-1.57" velocity="0.5"/>
  </joint>
  <joint name="wrist_roll" type="revolute">
    <parent link="wrist_link"/>
    <child link="hand_link"/>
    <origin xyz="0 0 0.060"/>
    <axis xyz="0 0 1"/>
    <limit effort="1000" lower="-1.57" upper="1.57" velocity="0.5"/>
  </joint>
  <joint name="grip_left" type="revolute">
    <parent link="hand_link"/>
    <child link="grip_left_link"/>
    <origin rpy="-1.57 0 0" xyz="0 +0.015 0.030"/>
    <axis xyz="-1 0 0"/>
    <limit effort="1000" lower="-1.57" upper="0" velocity="0.5"/>
  </joint>
  <joint name="grip_right" type="revolute">
    <parent link="hand_link"/>
    <child link="grip_right_link"/>
    <origin rpy="1.57 0 0" xyz="0 -0.015 0.030"/>
    <axis xyz="-1 0 0"/>
    <limit effort="1000" lower="0" upper="1.57" velocity="0.5"/>
    <mimic joint="grip_left" multiplier="-1"/>
  </joint>
  <joint name="tendon_left" type="revolute">
    <parent link="hand_link"/>
    <child link="tendon_left_link"/>
    <origin rpy="-1.57 0 0" xyz="0 +0.005 0.050"/>
    <axis xyz="-1 0 0"/>
    <limit effort="1000" lower="-1.57" upper="0" velocity="0.5"/>
    <mimic joint="grip_left"/>
  </joint>
  <joint name="tendon_right" type="revolute">
    <parent link="hand_link"/>
    <child link="tendon_right_link"/>
    <origin rpy="1.57 0 0" xyz="0 -0.005 0.050"/>
    <axis xyz="-1 0 0"/>
    <limit effort="1000" lower="0" upper="1.57" velocity="0.5"/>
    <mimic joint="grip_left" multiplier="-1"/>
  </joint>
  <joint name="finger_left" type="revolute">
    <parent link="grip_left_link"/>
    <child link="finger_left_link"/>
    <origin rpy="1.57 0 0" xyz="0 0 0.030"/>
    <axis xyz="-1 0 0"/>
    <limit effort="1000" lower="-1.57" upper="0" velocity="0.5"/>
    <mimic joint="grip_left" multiplier="-1"/>
  </joint>
  <joint name="finger_right" type="revolute">
    <parent link="grip_right_link"/>
    <child link="finger_right_link"/>
    <origin rpy="-1.57 0 0" xyz="0 0 0.030"/>
    <axis xyz="-1 0 0"/>
    <limit effort="1000" lower="0" upper="1.57" velocity="0.5"/>
    <mimic joint="grip_left"/>
  </joint>
</robot>
